Workbook

Sheet Config
A1: Tipo de cambio USD/ARS | B1: 1510
A2: Fuente | B2: Dólar oficial BNA venta, referencia 9-jul-2026 (dolarhoy.com / BNA) — ACTUALIZAR MANUALMENTE

Sheet Catálogo
A1: ID | B1: Servicio | C1: Categoría | D1: Descripción breve | E1: Precio ARS | F1: Precio USD | G1: Fuente del precio
A2: 6073 | B2: Aplicaciones Móviles | C2: Aplicaciones Móviles | D2: Desarrollo De Aplicaciones Móviles | E2: 6200 | F2: =E2/Config!$B$1 | G2: Estimado (mediana de categoría)
A3: 6653 | B3: Aplicaciones Móviles para Ecommerce: Crea tu Tienda Online en tu Bolsillo | C3: Aplicaciones Móviles | D3: Aplicaciones móviles para e-commerce: la clave para impulsar tu negocio online | E3: 2000 | F3: =E3/Config!$B$1 | G3: Real
A4: 8354 | B4: Aplicaciones móviles para e-commerce: Crea tu tienda online en tu bolsillo | C4: Aplicaciones Móviles | D4: Aplicaciones móviles para e-commerce: Crea tu tienda online en tu bolsillo | E4: 6200 | F4: =E4/Config!$B$1 | G4: Estimado (mediana de categoría)
A5: 6461 | B5: Creación de apps móviles | C5: Aplicaciones Móviles | D5: Servicio De Creación De Aplicaciones Móviles A Medida. | E5: 3000 | F5: =E5/Config!$B$1 | G5: Real
A6: 8172 | B6: Creación de apps móviles | C6: Aplicaciones Móviles | D6: Servicio De Creación De Aplicaciones Móviles A Medida. | E6: 6200 | F6: =E6/Config!$B$1 | G6: Estimado (mediana de categoría)
A7: 7581 | B7: Desarrollo a medida de aplicaciones móviles | C7: Aplicaciones Móviles | D7: Desarrollo De Apps Móviles | E7: 1080 | F7: =E7/Config!$B$1 | G7: Real
A8: 6157 | B8: Desarrollo de Aplicaciones Móviles Intuitivas | C8: Aplicaciones Móviles | D8: Desarrollo De Aplicaciones Móviles | E8: 9500 | F8: =E8/Config!$B$1 | G8: Real
A9: 7881 | B9: Desarrollo de Aplicaciones Móviles Intuitivas | C9: Aplicaciones Móviles | D9: Desarrollo De Aplicaciones Móviles | E9: 6200 | F9: =E9/Config!$B$1 | G9: Estimado (mediana de categoría)
A10: 6590 | B10: Desarrollo de Aplicaciones Móviles Nativas para Ecommerce: Mejora la Experiencia de Compra y Fideliza Clientes | C10: Aplicaciones Móviles | D10: Servicio de Desarrollo de Aplicación Móvil Nativa Para Ecommerce | E10: 12000 | F10: =E10/Config!$B$1 | G10: Real
A11: 5937 | B11: Desarrollo de Aplicaciones Móviles Nativas y Multiplataforma | C11: Aplicaciones Móviles | D11: Desarrollo De Apps Móviles | E11: 7000 | F11: =E11/Config!$B$1 | G11: Real
A12: 7719 | B12: Desarrollo de Aplicaciones Móviles Nativas y Multiplataforma | C12: Aplicaciones Móviles | D12: Desarrollo De Apps Móviles | E12: 6200 | F12: =E12/Config!$B$1 | G12: Estimado (mediana de categoría)
A13: 6677 | B13: Desarrollo de Aplicaciones Móviles para Ecommerce: Optimiza tu Tienda Virtual para Dispositivos Móviles | C13: Aplicaciones Móviles | D13: Servicios de Desarrollo de App Móvil para Ecommerce | E13: 3000 | F13: =E13/Config!$B$1 | G13: Real
... A31: 8211 | B31: Desarrollo de app móvil | C31: Aplicaciones Móviles | D31: Creación De Aplicaciones Móviles Para Brindar A Los Usuarios Una Experiencia De Marca Integral. | E31: 6200 | F31: =E31/Config!$B$1 | G31: Estimado (mediana de categoría)
A32: 6854 | B32: Diseño avanzado de aplicación móvil | C32: Aplicaciones Móviles | E32: 1 | F32: =E32/Config!$B$1 | G32: Real
A33: 6579 | B33: Diseño y Desarrollo de Apps Móviles para Ecommerce: Optimiza tu Tienda Online | C33: Aplicaciones Móviles | D33: Servicio de Diseño y Desarrollo de Aplicaciones Móviles para Ecommerce | E33: 8000 | F33: =E33/Config!$B$1 | G33: Real
A34: 8281 | B34: Diseño y Desarrollo de Apps Móviles para Ecommerce: Optimizá tu Tienda Online | C34: Aplicaciones Móviles | D34: Diseño y Desarrollo de Apps Móviles para Ecommerce: Optimiza tu Tienda Online | E34: 6200 | F34: =E34/Config!$B$1 | G34: Estimado (mediana de categoría)
A35: 5868 | B35: Servicios de Desarrollo de Aplicaciones Móviles | C35: Aplicaciones Móviles | D35: Desarrollo De Apps Móviles | E35: 8000 | F35: =E35/Config!$B$1 | G35: Real
A36: 7650 | B36: Servicios de Desarrollo de Aplicaciones Móviles | C36: Aplicaciones Móviles | D36: Desarrollo De Apps Móviles | E36: 6200 | F36: =E36/Config!$B$1 | G36: Estimado (mediana de categoría)
A37: 6704 | B37: Servicios de Desarrollo de Aplicaciones Móviles Ecommerce | C37: Aplicaciones Móviles | D37: Desarrollo De Aplicaciones Móviles Para Ecommerce. | E37: 10000 | F37: =E37/Config!$B$1 | G37: Real
A38: 6041 | B38: Servicios de Desarrollo de Aplicaciones Móviles Nativas | C38: Aplicaciones Móviles | D38: Aplicaciones Móviles Con Ar Y Vr | E38: 13500 | F38: =E38/Config!$B$1 | G38: Real
A39: 7787 | B39: Servicios de Desarrollo de Aplicaciones Móviles Nativas | C39: Aplicaciones Móviles | D39: Aplicaciones Móviles Con Ar Y Vr | E39: 6200 | F39: =E39/Config!$B$1 | G39: Estimado (mediana de categoría)
A40: 6012 | B40: Servicios de Desarrollo de Aplicaciones Móviles Nativas con Integración de Realidad Aumentada | C40: Aplicaciones Móviles | D40: Desarrollo De Aplicaciones | E40: 6200 | F40: =E40/Config!$B$1 | G40: Estimado (mediana de categoría)
A41: 7775 | B41: Servicios de Desarrollo de Aplicaciones Móviles Nativas con Integración de Realidad Aumentada | C41: Aplicaciones Móviles | D41: Desarrollo De Aplicaciones | E41: 6200 | F41: =E41/Config!$B$1 | G41: Estimado (mediana de categoría)
A42: 5972 | B42: Servicios de desarrollo de aplicaciones móviles con integración de tecnologías emergentes | C42: Aplicaciones Móviles | D42: Desarrollo De Aplicaciones Móviles Con Tecnologías Emergentes | E42: 10800 | F42: =E42/Config!$B$1 | G42: Real
A43: 7735 | B43: Servicios de desarrollo de aplicaciones móviles con integración de tecnologías emergentes | C43: Aplicaciones Móviles | D43: Desarrollo De Aplicaciones Móviles Con Tecnologías Emergentes | E43: 6200 | F43: =E43/Config!$B$1 | G43: Estimado (mediana de categoría)
A44: 5987 | B44: Servicios de desarrollo de aplicaciones móviles nativas con integración de realidad aumentada y realidad virtual | C44: Aplicaciones Móviles | D44: Desarrollo De Aplicaciones Móviles Con Realidad Aumentada Y Virtual | E44: 13500 | F44: =E44/Config!$B$1 | G44: Real
... A181: 7821 | B181: Soporte Técnico 24/7 | C181: Atención al Cliente | D181: Soporte Técnico | E181: 1000 | F181: =E181/Config!$B$1 | G181: Estimado (mediana de categoría)
A182: 7455 | B182: Soporte Técnico Adicional | C182: Atención al Cliente | E182: 1000 | F182: =E182/Config!$B$1 | G182: Estimado (mediana de categoría)
A183: 6979 | B183: Soporte Técnico Avanzado | C183: Atención al Cliente | D183: Soporte Técnico Avanzado. | E183: 1000 | F183: =E183/Config!$B$1 | G183: Real
A184: 6978 | B184: Soporte Técnico Básico | C184: Atención al Cliente | D184: Soporte Técnico Básico. | E184: 600 | F184: =E184/Config!$B$1 | G184: Real
A185: 6981 | B185: Soporte Técnico Básico (Horario Laboral) | C185: Atención al Cliente | D185: Soporte Técnico Básico. | E185: 250 | F185: =E185/Config!$B$1 | G185: Real
A186: 7470 | B186: Soporte Técnico Básico (Horario Laboral): Asistencia Experta para tus Dispositivos | C186: Atención al Cliente | D186: Soporte técnico remoto y telefónico durante el horario laboral para resolver problemas informáticos y de dispositivos. | E186: 24 | F186: =E186/Config!$B$1 | G186: Real
A187: 7479 | B187: Soporte Técnico Básico: Asistencia rápida y confiable para tus dispositivos | C187: Atención al Cliente | D187: Soporte Técnico Básico: Tu aliado tecnológico para una vida digital sin complicaciones. | E187: 1000 | F187: =E187/Config!$B$1 | G187: Estimado (mediana de categoría)
A188: 7509 | B188: Soporte Técnico Básico: Asistencia rápida y confiable para tus dispositivos | C188: Atención al Cliente | D188: Soporte Técnico Básico: Tu aliado tecnológico para una vida digital sin complicaciones. | E188: 1000 | F188: =E188/Config!$B$1 | G188: Estimado (mediana de categoría)
A189: 6149 | B189: Soporte Técnico Continuo | C189: Atención al Cliente | D189: Soporte Técnico Para Sistemas Y Aplicaciones. | E189: 2500 | F189: =E189/Config!$B$1 | G189: Real
A190: 7873 | B190: Soporte Técnico Continuo | C190: Atención al Cliente | D190: Soporte Técnico Para Sistemas Y Aplicaciones. | E190: 1000 | F190: =E190/Config!$B$1 | G190: Estimado (mediana de categoría)
A191: 7544 | B191: Soporte Técnico Continuo: Asistencia Experta 24/7 para tu Tranquilidad | C191: Atención al Cliente | D191: Soporte Técnico Continuo: Tu aliado tecnológico para un negocio sin interrupciones. Monitoreo proactivo, soporte remoto, soporte telefónico y gestión de incidentes para máxima disponibilidad, reducción de costos y tranquilidad. | E191: 0 | F191: =E191/Config!$B$1 | G191: Real
A192: 6221 | B192: Soporte Técnico Especializado | C192: Atención al Cliente | D192: Soporte Técnico Especializado | E192: 5500 | F192: =E192/Config!$B$1 | G192: Real
A193: 7945 | B193: Soporte Técnico Especializado | C193: Atención al Cliente | D193: Soporte Técnico Especializado | E193: 1000 | F193: =E193/Config!$B$1 | G193: Estimado (mediana de categoría)
...

Sheet Catálogo Clientum
A1: CATÁLOGO DE SERVICIOS CLIENTUM — con precios ARS y USD
A2: Tipo de cambio USD/ARS → hoja Config celda B1 | Fuente: clientum.com.ar/catalogo-servicios | Jul 2026
A3: Servicio | B3: Plan | C3: Nivel | D3: Precio ARS mín | E3: Precio ARS máx | F3: Precio ARS medio | G3: Precio USD mín | H3: Precio USD máx | I3: Impl. ARS mín | J3: Impl. ARS máx | K3: Mant. ARS mín | L3: Mant. ARS máx | M3: Soporte ARS mín | N3: Soporte ARS máx | O3: Tiempo resp.
A4: 🔌 Integración API Gateway | B4: Basic | C4: 1 | D4: 400000 | E4: 600000 | F4: 500000 | G4: =400000/Config!$B$1 | H4: =600000/Config!$B$1 | I4: 120000 | J4: 180000 | K4: 80000 | L4: 120000 | M4: 60000 | N4: 90000 | O4: 48 hs
A5: 🔌 Integración API Gateway | B5: Standard | C5: 2 | D5: 600000 | E5: 900000 | F5: 750000 | G5: =600000/Config!$B$1 | H5: =900000/Config!$B$1 | I5: 180000 | J5: 270000 | K5: 120000 | L5: 180000 | M5: 90000 | N5: 135000 | O5: 36 hs
A6: 🔌 Integración API Gateway | B6: Pro | C6: 3 | D6: 900000 | E6: 1300000 | F6: 1100000 | G6: =900000/Config!$B$1 | H6: =1300000/Config!$B$1 | I6: 270000 | J6: 390000 | K6: 180000 | L6: 260000 | M6: 135000 | N6: 195000 | O6: 24 hs
A7: 🔌 Integración API Gateway | B7: Advanced | C7: 4 | D7: 1300000 | E7: 1700000 | F7: 1500000 | G7: =1300000/Config!$B$1 | H7: =1700000/Config!$B$1 | I7: 390000 | J7: 510000 | K7: 260000 | L7: 340000 | M7: 195000 | N7: 255000 | O7: 18 hs
A8: 🔌 Integración API Gateway | B8: Enterprise | C8: 5 | D8: 1700000 | E8: 2200000 | F8: 1950000 | G8: =1700000/Config!$B$1 | H8: =2200000/Config!$B$1 | I8: 510000 | J8: 660000 | K8: 340000 | L8: 440000 | M8: 255000 | N8: 330000 | O8: 12 hs
A9: 🤖 Viaweb AI Copilot | B9: Basic | C9: 1 | D9: 600000 | E9: 900000 | F9: 750000 | G9: =600000/Config!$B$1 | H9: =900000/Config!$B$1 | I9: 180000 | J9: 270000 | K9: 120000 | L9: 180000 | M9: 90000 | N9: 135000 | O9: 48 hs
A10: 🤖 Viaweb AI Copilot | B10: Standard | C10: 2 | D10: 900000 | E10: 1300000 | F10: 1100000 | G10: =900000/Config!$B$1 | H10: =1300000/Config!$B$1 | I10: 270000 | J10: 390000 | K10: 180000 | L10: 260000 | M10: 135000 | N10: 195000 | O10: 36 hs
A11: 🤖 Viaweb AI Copilot | B11: Pro | C11: 3 | D11: 1300000 | E11: 1800000 | F11: 1550000 | G11: =1300000/Config!$B$1 | H11: =1800000/Config!$B$1 | I11: 390000 | J11: 540000 | K11: 260000 | L11: 360000 | M11: 195000 | N11: 270000 | O11: 24 hs
A12: 🤖 Viaweb AI Copilot | B12: Advanced | C12: 4 | D12: 1800000 | E12: 2300000 | F12: 2050000 | G12: =1800000/Config!$B$1 | H12: =2300000/Config!$B$1 | I12: 540000 | J12: 690000 | K12: 360000 | L12: 460000 | M12: 270000 | N12: 345000 | O12: 18 hs
A13: 🤖 Viaweb AI Copilot | B13: Enterprise | C13: 5 | D13: 2300000 | E13: 3000000 | F13: 2650000 | G13: =2300000/Config!$B$1 | H13: =3000000/Config!$B$1 | I13: 690000 | J13: 900000 | K13: 460000 | L13: 600000 | M13: 345000 | N13: 450000 | O13: 12 hs
A14: 💻 Desarrollo Web Personalizado | B14: Basic | C14: 1 | D14: 800000 | E14: 1500000 | F14: 1150000 | G14: =800000/Config!$B$1 | H14: =1500000/Config!$B$1 | I14: 240000 | J14: 450000 | K14: 160000 | L14: 300000 | M14: 120000 | N14: 225000 | O14: 48 hs
A15: 💻 Desarrollo Web Personalizado | B15: Standard | C15: 2 | D15: 1500000 | E15: 2000000 | F15: 1750000 | G15: =1500000/Config!$B$1 | H15: =2000000/Config!$B$1 | I15: 450000 | J15: 600000 | K15: 300000 | L15: 400000 | M15: 225000 | N15: 300000 | O15: 36 hs
A16: 💻 Desarrollo Web Personalizado | B16: Pro | C16: 3 | D16: 2000000 | E16: 3000000 | F16: 2500000 | G16: =2000000/Config!$B$1 | H16: =3000000/Config!$B$1 | I16: 600000 | J16: 900000 | K16: 400000 | L16: 600000 | M16: 300000 | N16: 450000 | O16: 24 hs
A17: 💻 Desarrollo Web Personalizado | B17: Advanced | C17: 4 | D17: 3000000 | E17: 4000000 | F17: 3500000 | G17: =3000000/Config!$B$1 | H17: =4000000/Config!$B$1 | I17: 900000 | J17: 1200000 | K17: 600000 | L17: 800000 | M17: 450000 | N17: 600000 | O17: 18 hs
A18: 💻 Desarrollo Web Personalizado | B18: Enterprise | C18: 5 | D18: 4000000 | E18: 5000000 | F18: 4500000 | G18: =4000000/Config!$B$1 | H18: =5000000/Config!$B$1 | I18: 1200000 | J18: 1500000 | K18: 800000 | L18: 1000000 | M18: 600000 | N18: 750000 | O18: 12 hs
A19: 💡 Precios de referencia en ARS. USD calculado con tipo de cambio editable en hoja Config (celda B1). Cada proyecto se cotiza a medida. Fuente: clientum.com.ar/catalogo-servicios · Jul 2026

Sheet Planes Clientum (SaaS)
A1: PLANES CLIENTUM — Suscripción mensual ARS y equivalente USD
A2: Precios en ARS/mes (Jul 2026). USD = ARS / tipo de cambio en Config!B1 | Fuente: clientum.com.ar/precios
A3: Plan | B3: Precio ARS/mes | C3: Precio USD/mes | D3: Conversaciones WhatsApp | E3: Contactos CRM | F3: Usuarios | G3: IA incluida | H3: Automatización | I3: AFIP integrada | J3: Portal cliente | K3: Soporte | L3: Destacado
A4: Demo | B4: Gratis | C4: — | D4: Prueba | E4: 100 | F4: 1 | G4: No | H4: No | I4: No | J4: No | K4: Email | L4: Gratis 14 días
A5: Starter | B5: 89990 | C5: =89990/Config!$B$1 | D5: 500 conv./mes | E5: 500 | F5: 1 | G5: No | H5: No | I5: No | J5: Básico | K5: Email | L5: —
A6: Pro | B6: 179990 | C6: =179990/Config!$B$1 | D6: Ilimitado | E6: Ilimitados | F6: 1 | G6: ✓ | H6: ✓ | I6: ✓ | J6: Personalizado | K6: Prioritario < 4 hs | L6: Más popular
A7: Business | B7: 349990 | C7: =349990/Config!$B$1 | D7: Multi-línea | E7: Ilimitados | F7: Hasta 5 | G7: ✓ | H7: ✓ | I7: ✓ | J7: Personalizado | K7: Manager dedicado | L7: Nuevo
A8: Enterprise | B8: A medida | C8: — | D8: Multi-línea + multi-sucursal | E8: Ilimitados | F8: Ilimitados | G8: ✓ | H8: ✓ | I8: ✓ | J8: Personalizado | K8: SLA garantizado | L8: A medida
A9: ⚡ Pagá anual y ahorrá 20% (≈ 2 meses gratis) | Pago con transferencia bancaria o MercadoPago | Sin tarjeta de crédito para Demo
A10: 💡 USD calculado con tipo de cambio editable en hoja Config!B1 | Fuente: clientum.com.ar/precios · Jul 2026

Sheet Resumen por Categoría
A1: Categoría | B1: Cantidad de servicios | C1: Precio ARS promedio | D1: Precio USD promedio | E1: Precio ARS mínimo | F1: Precio ARS máximo
A2: Aplicaciones Móviles | B2: =COUNTIF(Catálogo!$C$2:$C$2148,A2) | C2: =AVERAGEIF(Catálogo!$C$2:$C$2148,A2,Catálogo!$E$2:$E$2148) | D2: =AVERAGEIF(Catálogo!$C$2:$C$2148,A2,Catálogo!$F$2:$F$2148) | E2: {=MIN(IF(Catálogo!$C$2:$C$2148=A2,Catálogo!$E$2:$E$2148))} | F2: {=MAX(IF(Catálogo!$C$2:$C$2148=A2,Catálogo!$E$2:$E$2148))}
A3: Atención al Cliente | B3: =COUNTIF(Catálogo!$C$2:$C$2148,A3) | C3: =AVERAGEIF(Catálogo!$C$2:$C$2148,A3,Catálogo!$E$2:$E$2148) | D3: =AVERAGEIF(Catálogo!$C$2:$C$2148,A3,Catálogo!$F$2:$F$2148) | E3: {=MIN(IF(Catálogo!$C$2:$C$2148=A3,Catálogo!$E$2:$E$2148))} | F3: {=MAX(IF(Catálogo!$C$2:$C$2148=A3,Catálogo!$E$2:$E$2148))}
A4: Automatización de Procesos | B4: =COUNTIF(Catálogo!$C$2:$C$2148,A4) | C4: =AVERAGEIF(Catálogo!$C$2:$C$2148,A4,Catálogo!$E$2:$E$2148) | D4: =AVERAGEIF(Catálogo!$C$2:$C$2148,A4,Catálogo!$F$2:$F$2148) | E4: {=MIN(IF(Catálogo!$C$2:$C$2148=A4,Catálogo!$E$2:$E$2148))} | F4: {=MAX(IF(Catálogo!$C$2:$C$2148=A4,Catálogo!$E$2:$E$2148))}
A5: Business Intelligence | B5: =COUNTIF(Catálogo!$C$2:$C$2148,A5) | C5: =AVERAGEIF(Catálogo!$C$2:$C$2148,A5,Catálogo!$E$2:$E$2148) | D5: =AVERAGEIF(Catálogo!$C$2:$C$2148,A5,Catálogo!$F$2:$F$2148) | E5: {=MIN(IF(Catálogo!$C$2:$C$2148=A5,Catálogo!$E$2:$E$2148))} | F5: {=MAX(IF(Catálogo!$C$2:$C$2148=A5,Catálogo!$E$2:$E$2148))}
A6: Ciberseguridad | B6: =COUNTIF(Catálogo!$C$2:$C$2148,A6) | C6: =AVERAGEIF(Catálogo!$C$2:$C$2148,A6,Catálogo!$E$2:$E$2148) | D6: =AVERAGEIF(Catálogo!$C$2:$C$2148,A6,Catálogo!$F$2:$F$2148) | E6: {=MIN(IF(Catálogo!$C$2:$C$2148=A6,Catálogo!$E$2:$E$2148))} | F6: {=MAX(IF(Catálogo!$C$2:$C$2148=A6,Catálogo!$E$2:$E$2148))}
A7: Cloud Computing | B7: =COUNTIF(Catálogo!$C$2:$C$2148,A7) | C7: =AVERAGEIF(Catálogo!$C$2:$C$2148,A7,Catálogo!$E$2:$E$2148) | D7: =AVERAGEIF(Catálogo!$C$2:$C$2148,A7,Catálogo!$F$2:$F$2148) | E7: {=MIN(IF(Catálogo!$C$2:$C$2148=A7,Catálogo!$E$2:$E$2148))} | F7: {=MAX(IF(Catálogo!$C$2:$C$2148=A7,Catálogo!$E$2:$E$2148))}
A8: Desarrollo Web y E-Commerce | B8: =COUNTIF(Catálogo!$C$2:$C$2148,A8) | C8: =AVERAGEIF(Catálogo!$C$2:$C$2148,A8,Catálogo!$E$2:$E$2148) | D8: =AVERAGEIF(Catálogo!$C$2:$C$2148,A8,Catálogo!$F$2:$F$2148) | E8: {=MIN(IF(Catálogo!$C$2:$C$2148=A8,Catálogo!$E$2:$E$2148))} | F8: {=MAX(IF(Catálogo!$C$2:$C$2148=A8,Catálogo!$E$2:$E$2148))}
A9: ERP y CRM | B9: =COUNTIF(Catálogo!$C$2:$C$2148,A9) | C9: =AVERAGEIF(Catálogo!$C$2:$C$2148,A9,Catálogo!$E$2:$E$2148) | D9: =AVERAGEIF(Catálogo!$C$2:$C$2148,A9,Catálogo!$F$2:$F$2148) | E9: {=MIN(IF(Catálogo!$C$2:$C$2148=A9,Catálogo!$E$2:$E$2148))} | F9: {=MAX(IF(Catálogo!$C$2:$C$2148=A9,Catálogo!$E$2:$E$2148))}
A10: Formación y Capacitación | B10: =COUNTIF(Catálogo!$C$2:$C$2148,A10) | C10: =AVERAGEIF(Catálogo!$C$2:$C$2148,A10,Catálogo!$E$2:$E$2148) | D10: =AVERAGEIF(Catálogo!$C$2:$C$2148,A10,Catálogo!$F$2:$F$2148) | E10: {=MIN(IF(Catálogo!$C$2:$C$2148=A10,Catálogo!$E$2:$E$2148))} | F10: {=MAX(IF(Catálogo!$C$2:$C$2148=A10,Catálogo!$E$2:$E$2148))}
A11: Marketing Digital | B11: =COUNTIF(Catálogo!$C$2:$C$2148,A11) | C11: =AVERAGEIF(Catálogo!$C$2:$C$2148,A11,Catálogo!$E$2:$E$2148) | D11: =AVERAGEIF(Catálogo!$C$2:$C$2148,A11,Catálogo!$F$2:$F$2148) | E11: {=MIN(IF(Catálogo!$C$2:$C$2148=A11,Catálogo!$E$2:$E$2148))} | F11: {=MAX(IF(Catálogo!$C$2:$C$2148=A11,Catálogo!$E$2:$E$2148))}
A12: Plataformas de Comunicación | B12: =COUNTIF(Catálogo!$C$2:$C$2148,A12) | C12: =AVERAGEIF(Catálogo!$C$2:$C$2148,A12,Catálogo!$E$2:$E$2148) | D12: =AVERAGEIF(Catálogo!$C$2:$C$2148,A12,Catálogo!$F$2:$F$2148) | E12: {=MIN(IF(Catálogo!$C$2:$C$2148=A12,Catálogo!$E$2:$E$2148))} | F12: {=MAX(IF(Catálogo!$C$2:$C$2148=A12,Catálogo!$E$2:$E$2148))}
A13: Servicios de Hosting | B13: =COUNTIF(Catálogo!$C$2:$C$2148,A13) | C13: =AVERAGEIF(Catálogo!$C$2:$C$2148,A13,Catálogo!$E$2:$E$2148) | D13: =AVERAGEIF(Catálogo!$C$2:$C$2148,A13,Catálogo!$F$2:$F$2148) | E13: {=MIN(IF(Catálogo!$C$2:$C$2148=A13,Catálogo!$E$2:$E$2148))} | F13: {=MAX(IF(Catálogo!$C$2:$C$2148=A13,Catálogo!$E$2:$E$2148))}
A14: Soluciones por Industria | B14: =COUNTIF(Catálogo!$C$2:$C$2148,A14) | C14: =AVERAGEIF(Catálogo!$C$2:$C$2148,A14,Catálogo!$E$2:$E$2148) | D14: =AVERAGEIF(Catálogo!$C$2:$C$2148,A14,Catálogo!$F$2:$F$2148) | E14: {=MIN(IF(Catálogo!$C$2:$C$2148=A14,Catálogo!$E$2:$E$2148))} | F14: {=MAX(IF(Catálogo!$C$2:$C$2148=A14,Catálogo!$E$2:$E$2148))}
A15: TOTAL / PROMEDIO GENERAL | B15: =SUM(B2:B14) | C15: =AVERAGE(Catálogo!$E$2:$E$2148) | D15: =AVERAGE(Catálogo!$F$2:$F$2148) | E15: =MIN(Catálogo!$E$2:$E$2148) | F15: =MAX(Catálogo!$E$2:$E$2148)
